<?xml version="1.0" ?>
<!-- =================================================================================== -->
<!-- |    This document was autogenerated by xacro from robot.xacro                    | -->
<!-- |    EDITING THIS FILE BY HAND IS NOT RECOMMENDED                                 | -->
<!-- =================================================================================== -->
<robot name="robot">
  <material name="silver">
    <color rgba="0.700 0.700 0.700 1.000"/>
  </material>
  <transmission name="left_wheel_joint_tran">
    <type>transmission_interface/SimpleTransmission</type>
    <joint name="left_wheel_joint">
      <hardwareInterface>hardware_interface/EffortJointInterface</hardwareInterface>
    </joint>
    <actuator name="left_wheel_joint_actr">
      <hardwareInterface>hardware_interface/EffortJointInterface</hardwareInterface>
      <mechanicalReduction>1</mechanicalReduction>
    </actuator>
  </transmission>
  <transmission name="right_wheel_joint_tran">
    <type>transmission_interface/SimpleTransmission</type>
    <joint name="right_wheel_joint">
      <hardwareInterface>hardware_interface/EffortJointInterface</hardwareInterface>
    </joint>
    <actuator name="right_wheel_joint_actr">
      <hardwareInterface>hardware_interface/EffortJointInterface</hardwareInterface>
      <mechanicalReduction>1</mechanicalReduction>
    </actuator>
  </transmission>
  <transmission name="camera_mount_joint_tran">
    <type>transmission_interface/SimpleTransmission</type>
    <joint name="camera_mount_joint">
      <hardwareInterface>hardware_interface/EffortJointInterface</hardwareInterface>
    </joint>
    <actuator name="camera_mount_joint_actr">
      <hardwareInterface>hardware_interface/EffortJointInterface</hardwareInterface>
      <mechanicalReduction>1</mechanicalReduction>
    </actuator>
  </transmission>
  <transmission name="vision_mount_joint_tran">
    <type>transmission_interface/SimpleTransmission</type>
    <joint name="vision_mount_joint">
      <hardwareInterface>hardware_interface/EffortJointInterface</hardwareInterface>
    </joint>
    <actuator name="vision_mount_joint_actr">
      <hardwareInterface>hardware_interface/EffortJointInterface</hardwareInterface>
      <mechanicalReduction>1</mechanicalReduction>
    </actuator>
  </transmission>
  <transmission name="shoulder_joint_tran">
    <type>transmission_interface/SimpleTransmission</type>
    <joint name="shoulder_joint">
      <hardwareInterface>hardware_interface/EffortJointInterface</hardwareInterface>
    </joint>
    <actuator name="shoulder_joint_actr">
      <hardwareInterface>hardware_interface/EffortJointInterface</hardwareInterface>
      <mechanicalReduction>1</mechanicalReduction>
    </actuator>
  </transmission>
  <transmission name="upper_arm_joint_tran">
    <type>transmission_interface/SimpleTransmission</type>
    <joint name="upper_arm_joint">
      <hardwareInterface>hardware_interface/EffortJointInterface</hardwareInterface>
    </joint>
    <actuator name="upper_arm_joint_actr">
      <hardwareInterface>hardware_interface/EffortJointInterface</hardwareInterface>
      <mechanicalReduction>1</mechanicalReduction>
    </actuator>
  </transmission>
  <transmission name="elbow_joint _tran">
    <type>transmission_interface/SimpleTransmission</type>
    <joint name="elbow_joint ">
      <hardwareInterface>hardware_interface/EffortJointInterface</hardwareInterface>
    </joint>
    <actuator name="elbow_joint _actr">
      <hardwareInterface>hardware_interface/EffortJointInterface</hardwareInterface>
      <mechanicalReduction>1</mechanicalReduction>
    </actuator>
  </transmission>
  <transmission name="forearm_joint_tran">
    <type>transmission_interface/SimpleTransmission</type>
    <joint name="forearm_joint">
      <hardwareInterface>hardware_interface/EffortJointInterface</hardwareInterface>
    </joint>
    <actuator name="forearm_joint_actr">
      <hardwareInterface>hardware_interface/EffortJointInterface</hardwareInterface>
      <mechanicalReduction>1</mechanicalReduction>
    </actuator>
  </transmission>
  <transmission name="wrist_roll_joint_tran">
    <type>transmission_interface/SimpleTransmission</type>
    <joint name="wrist_roll_joint">
      <hardwareInterface>hardware_interface/EffortJointInterface</hardwareInterface>
    </joint>
    <actuator name="wrist_roll_joint_actr">
      <hardwareInterface>hardware_interface/EffortJointInterface</hardwareInterface>
      <mechanicalReduction>1</mechanicalReduction>
    </actuator>
  </transmission>
  <transmission name="wrist_pitch_joint_tran">
    <type>transmission_interface/SimpleTransmission</type>
    <joint name="wrist_pitch_joint">
      <hardwareInterface>hardware_interface/EffortJointInterface</hardwareInterface>
    </joint>
    <actuator name="wrist_pitch_joint_actr">
      <hardwareInterface>hardware_interface/EffortJointInterface</hardwareInterface>
      <mechanicalReduction>1</mechanicalReduction>
    </actuator>
  </transmission>
  <transmission name="gripper_joint_tran">
    <type>transmission_interface/SimpleTransmission</type>
    <joint name="gripper_joint">
      <hardwareInterface>hardware_interface/EffortJointInterface</hardwareInterface>
    </joint>
    <actuator name="gripper_joint_actr">
      <hardwareInterface>hardware_interface/EffortJointInterface</hardwareInterface>
      <mechanicalReduction>1</mechanicalReduction>
    </actuator>
  </transmission>
  <transmission name="tool_joint_tran">
    <type>transmission_interface/SimpleTransmission</type>
    <joint name="tool_joint">
      <hardwareInterface>hardware_interface/EffortJointInterface</hardwareInterface>
    </joint>
    <actuator name="tool_joint_actr">
      <hardwareInterface>hardware_interface/EffortJointInterface</hardwareInterface>
      <mechanicalReduction>1</mechanicalReduction>
    </actuator>
  </transmission>
  <transmission name="castor2_wheel_joint\_tran">
    <type>transmission_interface/SimpleTransmission</type>
    <joint name="castor2_wheel_joint\">
      <hardwareInterface>hardware_interface/EffortJointInterface</hardwareInterface>
    </joint>
    <actuator name="castor2_wheel_joint\_actr">
      <hardwareInterface>hardware_interface/EffortJointInterface</hardwareInterface>
      <mechanicalReduction>1</mechanicalReduction>
    </actuator>
  </transmission>
  <transmission name="castor2_joint_tran">
    <type>transmission_interface/SimpleTransmission</type>
    <joint name="castor2_joint">
      <hardwareInterface>hardware_interface/EffortJointInterface</hardwareInterface>
    </joint>
    <actuator name="castor2_joint_actr">
      <hardwareInterface>hardware_interface/EffortJointInterface</hardwareInterface>
      <mechanicalReduction>1</mechanicalReduction>
    </actuator>
  </transmission>
  <transmission name="castor1_wheel_joint_tran">
    <type>transmission_interface/SimpleTransmission</type>
    <joint name="castor1_wheel_joint">
      <hardwareInterface>hardware_interface/EffortJointInterface</hardwareInterface>
    </joint>
    <actuator name="castor1_wheel_joint_actr">
      <hardwareInterface>hardware_interface/EffortJointInterface</hardwareInterface>
      <mechanicalReduction>1</mechanicalReduction>
    </actuator>
  </transmission>
  <transmission name="castor1_joint_tran">
    <type>transmission_interface/SimpleTransmission</type>
    <joint name="castor1_joint">
      <hardwareInterface>hardware_interface/EffortJointInterface</hardwareInterface>
    </joint>
    <actuator name="castor1_joint_actr">
      <hardwareInterface>hardware_interface/EffortJointInterface</hardwareInterface>
      <mechanicalReduction>1</mechanicalReduction>
    </actuator>
  </transmission>
  <transmission name="castor4_wheel_joint_tran">
    <type>transmission_interface/SimpleTransmission</type>
    <joint name="castor4_wheel_joint">
      <hardwareInterface>hardware_interface/EffortJointInterface</hardwareInterface>
    </joint>
    <actuator name="castor4_wheel_joint_actr">
      <hardwareInterface>hardware_interface/EffortJointInterface</hardwareInterface>
      <mechanicalReduction>1</mechanicalReduction>
    </actuator>
  </transmission>
  <transmission name="castor4_joint_tran">
    <type>transmission_interface/SimpleTransmission</type>
    <joint name="castor4_joint">
      <hardwareInterface>hardware_interface/EffortJointInterface</hardwareInterface>
    </joint>
    <actuator name="castor4_joint_actr">
      <hardwareInterface>hardware_interface/EffortJointInterface</hardwareInterface>
      <mechanicalReduction>1</mechanicalReduction>
    </actuator>
  </transmission>
  <transmission name="castor3_wheel_joint_tran">
    <type>transmission_interface/SimpleTransmission</type>
    <joint name="castor3_wheel_joint">
      <hardwareInterface>hardware_interface/EffortJointInterface</hardwareInterface>
    </joint>
    <actuator name="castor3_wheel_joint_actr">
      <hardwareInterface>hardware_interface/EffortJointInterface</hardwareInterface>
      <mechanicalReduction>1</mechanicalReduction>
    </actuator>
  </transmission>
  <transmission name="castor_joint_tran">
    <type>transmission_interface/SimpleTransmission</type>
    <joint name="castor_joint">
      <hardwareInterface>hardware_interface/EffortJointInterface</hardwareInterface>
    </joint>
    <actuator name="castor_joint_actr">
      <hardwareInterface>hardware_interface/EffortJointInterface</hardwareInterface>
      <mechanicalReduction>1</mechanicalReduction>
    </actuator>
  </transmission>
  <gazebo reference="base_link">
    <material>Gazebo/Silver</material>
    <mu1>0.2</mu1>
    <mu2>0.2</mu2>
    <self_collide>true</self_collide>
    <gravity>true</gravity>
  </gazebo>
  <gazebo reference="left_wheel_link_2">
    <material>Gazebo/Silver</material>
    <mu1>0.2</mu1>
    <mu2>0.2</mu2>
    <self_collide>true</self_collide>
  </gazebo>
  <gazebo reference="right_wheel_link_1">
    <material>Gazebo/Silver</material>
    <mu1>0.2</mu1>
    <mu2>0.2</mu2>
    <self_collide>true</self_collide>
  </gazebo>
  <gazebo reference="camera_mount_link_1">
    <material>Gazebo/Silver</material>
    <mu1>0.2</mu1>
    <mu2>0.2</mu2>
    <self_collide>true</self_collide>
  </gazebo>
  <gazebo reference="vision_module_link_1">
    <material>Gazebo/Silver</material>
    <mu1>0.2</mu1>
    <mu2>0.2</mu2>
    <self_collide>true</self_collide>
  </gazebo>
  <gazebo reference="realsense_DCAM_1">
    <material>Gazebo/Silver</material>
    <mu1>0.2</mu1>
    <mu2>0.2</mu2>
    <self_collide>true</self_collide>
  </gazebo>
  <gazebo reference="shoulder_link__1">
    <material>Gazebo/Silver</material>
    <mu1>0.2</mu1>
    <mu2>0.2</mu2>
    <self_collide>true</self_collide>
  </gazebo>
  <gazebo reference="upper_arm_link_1">
    <material>Gazebo/Silver</material>
    <mu1>0.2</mu1>
    <mu2>0.2</mu2>
    <self_collide>true</self_collide>
  </gazebo>
  <gazebo reference="elbow_link_1">
    <material>Gazebo/Silver</material>
    <mu1>0.2</mu1>
    <mu2>0.2</mu2>
    <self_collide>true</self_collide>
  </gazebo>
  <gazebo reference="forearm_link_1">
    <material>Gazebo/Silver</material>
    <mu1>0.2</mu1>
    <mu2>0.2</mu2>
    <self_collide>true</self_collide>
  </gazebo>
  <gazebo reference="wrist_roll_link_1">
    <material>Gazebo/Silver</material>
    <mu1>0.2</mu1>
    <mu2>0.2</mu2>
    <self_collide>true</self_collide>
  </gazebo>
  <gazebo reference="wrist_pitch_link_1">
    <material>Gazebo/Silver</material>
    <mu1>0.2</mu1>
    <mu2>0.2</mu2>
    <self_collide>true</self_collide>
  </gazebo>
  <gazebo reference="claw_link_1">
    <material>Gazebo/Silver</material>
    <mu1>0.2</mu1>
    <mu2>0.2</mu2>
    <self_collide>true</self_collide>
  </gazebo>
  <gazebo reference="tool_link_1">
    <material>Gazebo/Silver</material>
    <mu1>0.2</mu1>
    <mu2>0.2</mu2>
    <self_collide>true</self_collide>
  </gazebo>
  <gazebo reference="castor2_wheel_link_1">
    <material>Gazebo/Silver</material>
    <mu1>0.2</mu1>
    <mu2>0.2</mu2>
    <self_collide>true</self_collide>
  </gazebo>
  <gazebo reference="castor2_link_1">
    <material>Gazebo/Silver</material>
    <mu1>0.2</mu1>
    <mu2>0.2</mu2>
    <self_collide>true</self_collide>
  </gazebo>
  <gazebo reference="castor1_wheel_link_1">
    <material>Gazebo/Silver</material>
    <mu1>0.2</mu1>
    <mu2>0.2</mu2>
    <self_collide>true</self_collide>
  </gazebo>
  <gazebo reference="castor1_link_1">
    <material>Gazebo/Silver</material>
    <mu1>0.2</mu1>
    <mu2>0.2</mu2>
    <self_collide>true</self_collide>
  </gazebo>
  <gazebo reference="castor4_wheel_link_1">
    <material>Gazebo/Silver</material>
    <mu1>0.2</mu1>
    <mu2>0.2</mu2>
    <self_collide>true</self_collide>
  </gazebo>
  <gazebo reference="castor4_link_1">
    <material>Gazebo/Silver</material>
    <mu1>0.2</mu1>
    <mu2>0.2</mu2>
    <self_collide>true</self_collide>
  </gazebo>
  <gazebo reference="castor3_wheel_link_1">
    <material>Gazebo/Silver</material>
    <mu1>0.2</mu1>
    <mu2>0.2</mu2>
    <self_collide>true</self_collide>
  </gazebo>
  <gazebo reference="castor3_link_1">
    <material>Gazebo/Silver</material>
    <mu1>0.2</mu1>
    <mu2>0.2</mu2>
    <self_collide>true</self_collide>
  </gazebo>
  <ros2_control name="GazeboSystem" type="system">
    <hardware>
      <plugin>gazebo_ros2_control/GazeboSystem</plugin>
    </hardware>
    <joint name="left_wheel_joint">
      <command_interface name="velocity">
        <param name="min">-1</param>
        <param name="max">1</param>
      </command_interface>
      <state_interface name="position"/>
      <state_interface name="velocity"/>
    </joint>
    <joint name="right_wheel_joint">
      <command_interface name="velocity">
        <param name="min">-1</param>
        <param name="max">1</param>
      </command_interface>
      <state_interface name="position"/>
      <state_interface name="velocity"/>
    </joint>
  </ros2_control>
  <gazebo>
    <!-- Joint state publisher -->
    <plugin filename="libgazebo_ros2_control.so" name="gazebo_ros2_control">
      <parameters>/home/arvi/bot_ws/install/bot/share/bot/config/diff_drive_controller.yaml</parameters>
    </plugin>
  </gazebo>
  <gazebo reference="vision_module_link_1">
    <material>Gazebo/Red</material>
    <sensor name="camera" type="depth">
      <pose> 0 0 0 0 0 0 </pose>
      <visualize>true</visualize>
      <update_rate>10</update_rate>
      <camera>
        <horizontal_fov>1.089</horizontal_fov>
        <image>
          <format>R8G8B8</format>
          <width>640</width>
          <height>480</height>
        </image>
        <clip>
          <near>0.05</near>
          <far>8.0</far>
        </clip>
      </camera>
      <plugin filename="libgazebo_ros_camera.so" name="camera_controller">
        <frame_name>realsense_DCAM_1</frame_name>
        <min_depth>0.1</min_depth>
        <max_depth>100.0</max_depth>
      </plugin>
    </sensor>
  </gazebo>
  <link name="base_link">
    <inertial>
      <origin rpy="0 0 0" xyz="-0.008818686971159602 -0.014397245080040028 0.30864055465963175"/>
      <mass value="3.7819615734159022"/>
      <inertia ixx="0.408975" ixy="0.000186" ixz="-0.001099" iyy="0.403097" iyz="0.026021" izz="0.070024"/>
    </inertial>
    <visual>
      <origin rpy="0 0 0" xyz="0 0 0"/>
      <geometry>
        <mesh filename="file:///home/arvi/bot_ws/install/robot_description/share/robot_description/meshes/base_link.stl" scale="0.001 0.001 0.001"/>
      </geometry>
      <material name="silver"/>
    </visual>
    <collision>
      <origin rpy="0 0 0" xyz="0 0 0"/>
      <geometry>
        <mesh filename="file:///home/arvi/bot_ws/install/robot_description/share/robot_description/meshes/base_link.stl" scale="0.001 0.001 0.001"/>
      </geometry>
    </collision>
  </link>
  <link name="left_wheel_link_2">
    <inertial>
      <origin rpy="0 0 0" xyz="0.0004044659102567551 0.01599521235557283 3.414141627883227e-07"/>
      <mass value="0.41626102660064224"/>
      <inertia ixx="0.000442" ixy="9e-06" ixz="-0.0" iyy="0.000813" iyz="0.0" izz="0.000442"/>
    </inertial>
    <visual>
      <origin rpy="0 0 0" xyz="0.0074 -0.134581 -0.062625"/>
      <geometry>
        <mesh filename="file:///home/arvi/bot_ws/install/robot_description/share/robot_description/meshes/left_wheel_link_2.stl" scale="0.001 0.001 0.001"/>
      </geometry>
      <material name="silver"/>
    </visual>
    <collision>
      <origin rpy="0 0 0" xyz="0.0074 -0.134581 -0.062625"/>
      <geometry>
        <mesh filename="file:///home/arvi/bot_ws/install/robot_description/share/robot_description/meshes/left_wheel_link_2.stl" scale="0.001 0.001 0.001"/>
      </geometry>
    </collision>
  </link>
  <link name="right_wheel_link_1">
    <inertial>
      <origin rpy="0 0 0" xyz="5.887709386826617e-06 -0.01599979280325428 3.4141424240519136e-07"/>
      <mass value="0.41626102660064224"/>
      <inertia ixx="0.000442" ixy="-0.0" ixz="0.0" iyy="0.000813" iyz="0.0" izz="0.000442"/>
    </inertial>
    <visual>
      <origin rpy="0 0 0" xyz="0.010756 0.134446 -0.062625"/>
      <geometry>
        <mesh filename="file:///home/arvi/bot_ws/install/robot_description/share/robot_description/meshes/right_wheel_link_1.stl" scale="0.001 0.001 0.001"/>
      </geometry>
      <material name="silver"/>
    </visual>
    <collision>
      <origin rpy="0 0 0" xyz="0.010756 0.134446 -0.062625"/>
      <geometry>
        <mesh filename="file:///home/arvi/bot_ws/install/robot_description/share/robot_description/meshes/right_wheel_link_1.stl" scale="0.001 0.001 0.001"/>
      </geometry>
    </collision>
  </link>
  <link name="camera_mount_link_1">
    <inertial>
      <origin rpy="0 0 0" xyz="0.04206860670983411 0.005537273638627808 0.02828214954932806"/>
      <mass value="0.04598593540117349"/>
      <inertia ixx="1.6e-05" ixy="-1e-06" ixz="-0.0" iyy="1.6e-05" iyz="-0.0" izz="1.3e-05"/>
    </inertial>
    <visual>
      <origin rpy="0 0 0" xyz="-0.001158 0.011992 -0.863809"/>
      <geometry>
        <mesh filename="file:///home/arvi/bot_ws/install/robot_description/share/robot_description/meshes/camera_mount_link_1.stl" scale="0.001 0.001 0.001"/>
      </geometry>
      <material name="silver"/>
    </visual>
    <collision>
      <origin rpy="0 0 0" xyz="-0.001158 0.011992 -0.863809"/>
      <geometry>
        <mesh filename="file:///home/arvi/bot_ws/install/robot_description/share/robot_description/meshes/camera_mount_link_1.stl" scale="0.001 0.001 0.001"/>
      </geometry>
    </collision>
  </link>
  <link name="vision_module_link_1">
    <inertial>
      <origin rpy="0 0 0" xyz="0.012630200025580192 -0.0255280951968587 0.03589133223318708"/>
      <mass value="0.017455574975837183"/>
      <inertia ixx="1.2e-05" ixy="0.0" ixz="-2e-06" iyy="7e-06" iyz="0.0" izz="9e-06"/>
    </inertial>
    <visual>
      <origin rpy="0 0 0" xyz="-0.048156 -0.019845 -0.901897"/>
      <geometry>
        <mesh filename="file:///home/arvi/bot_ws/install/robot_description/share/robot_description/meshes/vision_module_link_1.stl" scale="0.001 0.001 0.001"/>
      </geometry>
      <material name="silver"/>
    </visual>
    <collision>
      <origin rpy="0 0 0" xyz="-0.048156 -0.019845 -0.901897"/>
      <geometry>
        <mesh filename="file:///home/arvi/bot_ws/install/robot_description/share/robot_description/meshes/vision_module_link_1.stl" scale="0.001 0.001 0.001"/>
      </geometry>
    </collision>
  </link>
  <link name="realsense_DCAM_1">
    <inertial>
      <origin rpy="0 0 0" xyz="0.011657410142899255 -0.0011559566930996867 0.0010283014584634431"/>
      <mass value="0.03866336197375993"/>
      <inertia ixx="2.5e-05" ixy="-0.0" ixz="-0.0" iyy="4e-06" iyz="0.0" izz="2.5e-05"/>
    </inertial>
    <visual>
      <origin rpy="0 0 0" xyz="-0.073593 0.005001 -0.950168"/>
      <geometry>
        <mesh filename="file:///home/arvi/bot_ws/install/robot_description/share/robot_description/meshes/realsense_DCAM_1.stl" scale="0.001 0.001 0.001"/>
      </geometry>
      <material name="silver"/>
    </visual>
    <collision>
      <origin rpy="0 0 0" xyz="-0.073593 0.005001 -0.950168"/>
      <geometry>
        <mesh filename="file:///home/arvi/bot_ws/install/robot_description/share/robot_description/meshes/realsense_DCAM_1.stl" scale="0.001 0.001 0.001"/>
      </geometry>
    </collision>
  </link>
  <link name="shoulder_link__1">
    <inertial>
      <origin rpy="0 0 0" xyz="0.0013129127998000381 -0.037788605063542674 -0.00021152048147132785"/>
      <mass value="0.7384717851769812"/>
      <inertia ixx="0.002011" ixy="-1.8e-05" ixz="1e-06" iyy="0.000588" iyz="-4.4e-05" izz="0.001996"/>
    </inertial>
    <visual>
      <origin rpy="0 0 0" xyz="0.014115 0.160026 -0.802564"/>
      <geometry>
        <mesh filename="file:///home/arvi/bot_ws/install/robot_description/share/robot_description/meshes/shoulder_link__1.stl" scale="0.001 0.001 0.001"/>
      </geometry>
      <material name="silver"/>
    </visual>
    <collision>
      <origin rpy="0 0 0" xyz="0.014115 0.160026 -0.802564"/>
      <geometry>
        <mesh filename="file:///home/arvi/bot_ws/install/robot_description/share/robot_description/meshes/shoulder_link__1.stl" scale="0.001 0.001 0.001"/>
      </geometry>
    </collision>
  </link>
  <link name="upper_arm_link_1">
    <inertial>
      <origin rpy="0 0 0" xyz="-0.004621761726250605 -0.031378561078528766 -0.04037693867645409"/>
      <mass value="0.2692664645760716"/>
      <inertia ixx="0.000933" ixy="7e-06" ixz="-1.3e-05" iyy="0.000609" iyz="3.1e-05" izz="0.000516"/>
    </inertial>
    <visual>
      <origin rpy="0 0 0" xyz="0.01365 0.26875 -0.840372"/>
      <geometry>
        <mesh filename="file:///home/arvi/bot_ws/install/robot_description/share/robot_description/meshes/upper_arm_link_1.stl" scale="0.001 0.001 0.001"/>
      </geometry>
      <material name="silver"/>
    </visual>
    <collision>
      <origin rpy="0 0 0" xyz="0.01365 0.26875 -0.840372"/>
      <geometry>
        <mesh filename="file:///home/arvi/bot_ws/install/robot_description/share/robot_description/meshes/upper_arm_link_1.stl" scale="0.001 0.001 0.001"/>
      </geometry>
    </collision>
  </link>
  <link name="elbow_link_1">
    <inertial>
      <origin rpy="0 0 0" xyz="-0.001525479667072803 -0.10807208280337188 0.004053721223209128"/>
      <mass value="0.42876113959991835"/>
      <inertia ixx="0.004415" ixy="-5.7e-05" ixz="-0.0" iyy="0.0003" iyz="0.000167" izz="0.004387"/>
    </inertial>
    <visual>
      <origin rpy="0 0 0" xyz="0.017637 0.369043 -0.81256"/>
      <geometry>
        <mesh filename="file:///home/arvi/bot_ws/install/robot_description/share/robot_description/meshes/elbow_link_1.stl" scale="0.001 0.001 0.001"/>
      </geometry>
      <material name="silver"/>
    </visual>
    <collision>
      <origin rpy="0 0 0" xyz="0.017637 0.369043 -0.81256"/>
      <geometry>
        <mesh filename="file:///home/arvi/bot_ws/install/robot_description/share/robot_description/meshes/elbow_link_1.stl" scale="0.001 0.001 0.001"/>
      </geometry>
    </collision>
  </link>
  <link name="forearm_link_1">
    <inertial>
      <origin rpy="0 0 0" xyz="-0.003766768283010126 -0.045093417689484716 -0.04947538181758737"/>
      <mass value="0.09520827317126657"/>
      <inertia ixx="0.00019" ixy="3e-06" ixz="0.0" iyy="0.000134" iyz="-1e-05" izz="0.000138"/>
    </inertial>
    <visual>
      <origin rpy="0 0 0" xyz="0.019409 0.582379 -0.864308"/>
      <geometry>
        <mesh filename="file:///home/arvi/bot_ws/install/robot_description/share/robot_description/meshes/forearm_link_1.stl" scale="0.001 0.001 0.001"/>
      </geometry>
      <material name="silver"/>
    </visual>
    <collision>
      <origin rpy="0 0 0" xyz="0.019409 0.582379 -0.864308"/>
      <geometry>
        <mesh filename="file:///home/arvi/bot_ws/install/robot_description/share/robot_description/meshes/forearm_link_1.stl" scale="0.001 0.001 0.001"/>
      </geometry>
    </collision>
  </link>
  <link name="wrist_roll_link_1">
    <inertial>
      <origin rpy="0 0 0" xyz="-0.0029368994773587356 -0.06645522974448603 -0.0019976020466210276"/>
      <mass value="0.3567121669099486"/>
      <inertia ixx="0.000213" ixy="-3e-06" ixz="-1e-06" iyy="0.000108" iyz="-2.9e-05" izz="0.000181"/>
    </inertial>
    <visual>
      <origin rpy="0 0 0" xyz="0.013683 0.669372 -0.811607"/>
      <geometry>
        <mesh filename="file:///home/arvi/bot_ws/install/robot_description/share/robot_description/meshes/wrist_roll_link_1.stl" scale="0.001 0.001 0.001"/>
      </geometry>
      <material name="silver"/>
    </visual>
    <collision>
      <origin rpy="0 0 0" xyz="0.013683 0.669372 -0.811607"/>
      <geometry>
        <mesh filename="file:///home/arvi/bot_ws/install/robot_description/share/robot_description/meshes/wrist_roll_link_1.stl" scale="0.001 0.001 0.001"/>
      </geometry>
    </collision>
  </link>
  <link name="wrist_pitch_link_1">
    <inertial>
      <origin rpy="0 0 0" xyz="0.005797954804564947 -0.03840456934937542 0.024255817132108004"/>
      <mass value="0.06331163881843703"/>
      <inertia ixx="6.3e-05" ixy="5e-06" ixz="-4e-06" iyy="5.7e-05" iyz="2e-05" izz="5.9e-05"/>
    </inertial>
    <visual>
      <origin rpy="0 0 0" xyz="0.017156 0.748244 -0.782163"/>
      <geometry>
        <mesh filename="file:///home/arvi/bot_ws/install/robot_description/share/robot_description/meshes/wrist_pitch_link_1.stl" scale="0.001 0.001 0.001"/>
      </geometry>
      <material name="silver"/>
    </visual>
    <collision>
      <origin rpy="0 0 0" xyz="0.017156 0.748244 -0.782163"/>
      <geometry>
        <mesh filename="file:///home/arvi/bot_ws/install/robot_description/share/robot_description/meshes/wrist_pitch_link_1.stl" scale="0.001 0.001 0.001"/>
      </geometry>
    </collision>
  </link>
  <link name="claw_link_1">
    <inertial>
      <origin rpy="0 0 0" xyz="0.0012291857915583577 -0.0401851920171451 0.028895449651581417"/>
      <mass value="0.07304031418361377"/>
      <inertia ixx="0.000124" ixy="2e-06" ixz="-0.0" iyy="6.2e-05" iyz="1.5e-05" izz="7.4e-05"/>
    </inertial>
    <visual>
      <origin rpy="0 0 0" xyz="0.000253 0.813976 -0.82299"/>
      <geometry>
        <mesh filename="file:///home/arvi/bot_ws/install/robot_description/share/robot_description/meshes/claw_link_1.stl" scale="0.001 0.001 0.001"/>
      </geometry>
      <material name="silver"/>
    </visual>
    <collision>
      <origin rpy="0 0 0" xyz="0.000253 0.813976 -0.82299"/>
      <geometry>
        <mesh filename="file:///home/arvi/bot_ws/install/robot_description/share/robot_description/meshes/claw_link_1.stl" scale="0.001 0.001 0.001"/>
      </geometry>
    </collision>
  </link>
  <link name="tool_link_1">
    <inertial>
      <origin rpy="0 0 0" xyz="0.00194242803604251 -0.04012285078947431 -0.0738790925418491"/>
      <mass value="0.015310818324295426"/>
      <inertia ixx="1.7e-05" ixy="1e-06" ixz="0.0" iyy="1e-06" iyz="-0.0" izz="1.8e-05"/>
    </inertial>
    <visual>
      <origin rpy="0 0 0" xyz="2.4e-05 0.840557 -0.87294"/>
      <geometry>
        <mesh filename="file:///home/arvi/bot_ws/install/robot_description/share/robot_description/meshes/tool_link_1.stl" scale="0.001 0.001 0.001"/>
      </geometry>
      <material name="silver"/>
    </visual>
    <collision>
      <origin rpy="0 0 0" xyz="2.4e-05 0.840557 -0.87294"/>
      <geometry>
        <mesh filename="file:///home/arvi/bot_ws/install/robot_description/share/robot_description/meshes/tool_link_1.stl" scale="0.001 0.001 0.001"/>
      </geometry>
    </collision>
  </link>
  <link name="castor2_wheel_link_1">
    <inertial>
      <origin rpy="0 0 0" xyz="-2.7765768996046436e-05 -0.007500186231998884 2.780251692341418e-07"/>
      <mass value="0.008745712385534371"/>
      <inertia ixx="1e-06" ixy="0.0" ixz="0.0" iyy="1e-06" iyz="0.0" izz="1e-06"/>
    </inertial>
    <visual>
      <origin rpy="0 0 0" xyz="0.167245 0.171855 -0.016186"/>
      <geometry>
        <mesh filename="file:///home/arvi/bot_ws/install/robot_description/share/robot_description/meshes/castor2_wheel_link_1.stl" scale="0.001 0.001 0.001"/>
      </geometry>
      <material name="silver"/>
    </visual>
    <collision>
      <origin rpy="0 0 0" xyz="0.167245 0.171855 -0.016186"/>
      <geometry>
        <mesh filename="file:///home/arvi/bot_ws/install/robot_description/share/robot_description/meshes/castor2_wheel_link_1.stl" scale="0.001 0.001 0.001"/>
      </geometry>
    </collision>
  </link>
  <link name="castor2_link_1">
    <inertial>
      <origin rpy="0 0 0" xyz="0.003516920306617821 -0.0005065823270779812 -0.005952028114260963"/>
      <mass value="0.002215422344468901"/>
      <inertia ixx="1e-06" ixy="0.0" ixz="0.0" iyy="1e-06" iyz="0.0" izz="1e-06"/>
    </inertial>
    <visual>
      <origin rpy="0 0 0" xyz="0.181264 0.178803 -0.037117"/>
      <geometry>
        <mesh filename="file:///home/arvi/bot_ws/install/robot_description/share/robot_description/meshes/castor2_link_1.stl" scale="0.001 0.001 0.001"/>
      </geometry>
      <material name="silver"/>
    </visual>
    <collision>
      <origin rpy="0 0 0" xyz="0.181264 0.178803 -0.037117"/>
      <geometry>
        <mesh filename="file:///home/arvi/bot_ws/install/robot_description/share/robot_description/meshes/castor2_link_1.stl" scale="0.001 0.001 0.001"/>
      </geometry>
    </collision>
  </link>
  <link name="castor1_wheel_link_1">
    <inertial>
      <origin rpy="0 0 0" xyz="0.0001186002369346073 0.0074990583088189455 2.7802536406093536e-07"/>
      <mass value="0.00874571238559159"/>
      <inertia ixx="1e-06" ixy="0.0" ixz="0.0" iyy="1e-06" iyz="-0.0" izz="1e-06"/>
    </inertial>
    <visual>
      <origin rpy="0 0 0" xyz="-0.144451 0.191036 -0.01597"/>
      <geometry>
        <mesh filename="file:///home/arvi/bot_ws/install/robot_description/share/robot_description/meshes/castor1_wheel_link_1.stl" scale="0.001 0.001 0.001"/>
      </geometry>
      <material name="silver"/>
    </visual>
    <collision>
      <origin rpy="0 0 0" xyz="-0.144451 0.191036 -0.01597"/>
      <geometry>
        <mesh filename="file:///home/arvi/bot_ws/install/robot_description/share/robot_description/meshes/castor1_wheel_link_1.stl" scale="0.001 0.001 0.001"/>
      </geometry>
    </collision>
  </link>
  <link name="castor1_link_1">
    <inertial>
      <origin rpy="0 0 0" xyz="-0.003358398581431443 0.0005470762693611797 -0.00616802811427964"/>
      <mass value="0.0058520590231254"/>
      <inertia ixx="1e-06" ixy="0.0" ixz="-0.0" iyy="1e-06" iyz="0.0" izz="1e-06"/>
    </inertial>
    <visual>
      <origin rpy="0 0 0" xyz="-0.158401 0.184256 -0.037117"/>
      <geometry>
        <mesh filename="file:///home/arvi/bot_ws/install/robot_description/share/robot_description/meshes/castor1_link_1.stl" scale="0.001 0.001 0.001"/>
      </geometry>
      <material name="silver"/>
    </visual>
    <collision>
      <origin rpy="0 0 0" xyz="-0.158401 0.184256 -0.037117"/>
      <geometry>
        <mesh filename="file:///home/arvi/bot_ws/install/robot_description/share/robot_description/meshes/castor1_link_1.stl" scale="0.001 0.001 0.001"/>
      </geometry>
    </collision>
  </link>
  <link name="castor4_wheel_link_1">
    <inertial>
      <origin rpy="0 0 0" xyz="-2.7885297346708082e-05 -0.007500151699322638 4.780253358600828e-07"/>
      <mass value="0.008745712385538338"/>
      <inertia ixx="1e-06" ixy="0.0" ixz="0.0" iyy="1e-06" iyz="0.0" izz="1e-06"/>
    </inertial>
    <visual>
      <origin rpy="0 0 0" xyz="0.191077 -0.190841 -0.015697"/>
      <geometry>
        <mesh filename="file:///home/arvi/bot_ws/install/robot_description/share/robot_description/meshes/castor4_wheel_link_1.stl" scale="0.001 0.001 0.001"/>
      </geometry>
      <material name="silver"/>
    </visual>
    <collision>
      <origin rpy="0 0 0" xyz="0.191077 -0.190841 -0.015697"/>
      <geometry>
        <mesh filename="file:///home/arvi/bot_ws/install/robot_description/share/robot_description/meshes/castor4_wheel_link_1.stl" scale="0.001 0.001 0.001"/>
      </geometry>
    </collision>
  </link>
  <link name="castor4_link_1">
    <inertial>
      <origin rpy="0 0 0" xyz="-0.003460571373861243 -0.000493755604240087 -0.006440828114108184"/>
      <mass value="0.0058520590231254"/>
      <inertia ixx="1e-06" ixy="0.0" ixz="-0.0" iyy="1e-06" iyz="-0.0" izz="1e-06"/>
    </inertial>
    <visual>
      <origin rpy="0 0 0" xyz="0.17717 -0.183789 -0.037117"/>
      <geometry>
        <mesh filename="file:///home/arvi/bot_ws/install/robot_description/share/robot_description/meshes/castor4_link_1.stl" scale="0.001 0.001 0.001"/>
      </geometry>
      <material name="silver"/>
    </visual>
    <collision>
      <origin rpy="0 0 0" xyz="0.17717 -0.183789 -0.037117"/>
      <geometry>
        <mesh filename="file:///home/arvi/bot_ws/install/robot_description/share/robot_description/meshes/castor4_link_1.stl" scale="0.001 0.001 0.001"/>
      </geometry>
    </collision>
  </link>
  <link name="castor3_wheel_link_1">
    <inertial>
      <origin rpy="0 0 0" xyz="-2.8571723080766942e-05 -0.0074996766153433425 -2.197468448872364e-08"/>
      <mass value="0.008745712385538335"/>
      <inertia ixx="1e-06" ixy="0.0" ixz="0.0" iyy="1e-06" iyz="0.0" izz="1e-06"/>
    </inertial>
    <visual>
      <origin rpy="0 0 0" xyz="-0.146216 -0.185648 -0.015884"/>
      <geometry>
        <mesh filename="file:///home/arvi/bot_ws/install/robot_description/share/robot_description/meshes/castor3_wheel_link_1.stl" scale="0.001 0.001 0.001"/>
      </geometry>
      <material name="silver"/>
    </visual>
    <collision>
      <origin rpy="0 0 0" xyz="-0.146216 -0.185648 -0.015884"/>
      <geometry>
        <mesh filename="file:///home/arvi/bot_ws/install/robot_description/share/robot_description/meshes/castor3_wheel_link_1.stl" scale="0.001 0.001 0.001"/>
      </geometry>
    </collision>
  </link>
  <link name="castor3_link_1">
    <inertial>
      <origin rpy="0 0 0" xyz="-0.003485257799595687 -0.0004942805202605982 -0.0062543281141285365"/>
      <mass value="0.0058520590231254"/>
      <inertia ixx="1e-06" ixy="0.0" ixz="-0.0" iyy="1e-06" iyz="-0.0" izz="1e-06"/>
    </inertial>
    <visual>
      <origin rpy="0 0 0" xyz="-0.160147 -0.178597 -0.037117"/>
      <geometry>
        <mesh filename="file:///home/arvi/bot_ws/install/robot_description/share/robot_description/meshes/castor3_link_1.stl" scale="0.001 0.001 0.001"/>
      </geometry>
      <material name="silver"/>
    </visual>
    <collision>
      <origin rpy="0 0 0" xyz="-0.160147 -0.178597 -0.037117"/>
      <geometry>
        <mesh filename="file:///home/arvi/bot_ws/install/robot_description/share/robot_description/meshes/castor3_link_1.stl" scale="0.001 0.001 0.001"/>
      </geometry>
    </collision>
  </link>
  <joint name="left_wheel_joint" type="continuous">
    <origin rpy="0 0 0" xyz="-0.0074 0.134581 0.062625"/>
    <parent link="base_link"/>
    <child link="left_wheel_link_2"/>
    <axis xyz="0.025282 0.99968 0.0"/>
  </joint>
  <joint name="right_wheel_joint" type="continuous">
    <origin rpy="0 0 0" xyz="-0.010756 -0.134446 0.062625"/>
    <parent link="base_link"/>
    <child link="right_wheel_link_1"/>
    <axis xyz="0.00034 -1.0 -0.0"/>
  </joint>
  <joint name="camera_mount_joint" type="revolute">
    <origin rpy="0 0 0" xyz="0.001158 -0.011992 0.863809"/>
    <parent link="base_link"/>
    <child link="camera_mount_link_1"/>
    <axis xyz="-5.5e-05 0.003611 0.999993"/>
    <limit effort="100" lower="-1.570796" upper="1.570796" velocity="100"/>
  </joint>
  <joint name="vision_mount_joint" type="revolute">
    <origin rpy="0 0 0" xyz="0.046998 0.031837 0.038088"/>
    <parent link="camera_mount_link_1"/>
    <child link="vision_module_link_1"/>
    <axis xyz="1.1e-05 0.999993 -0.003611"/>
    <limit effort="100" lower="-1.570796" upper="1.570796" velocity="100"/>
  </joint>
  <joint name="realsense_joint" type="fixed">
    <origin rpy="0 0 0" xyz="0.025437 -0.024846 0.048271"/>
    <parent link="vision_module_link_1"/>
    <child link="realsense_DCAM_1"/>
  </joint>
  <joint name="shoulder_joint" type="continuous">
    <origin rpy="0 0 0" xyz="-0.014115 -0.160026 0.802564"/>
    <parent link="base_link"/>
    <child link="shoulder_link__1"/>
    <axis xyz="-0.012409 -0.999916 0.003701"/>
  </joint>
  <joint name="upper_arm_joint" type="revolute">
    <origin rpy="0 0 0" xyz="0.000465 -0.108724 0.037808"/>
    <parent link="shoulder_link__1"/>
    <child link="upper_arm_link_1"/>
    <axis xyz="0.003407 0.00366 0.999987"/>
    <limit effort="100" lower="-1.570796" upper="1.570796" velocity="100"/>
  </joint>
  <joint name="elbow_joint " type="continuous">
    <origin rpy="0 0 0" xyz="-0.003987 -0.100293 -0.027812"/>
    <parent link="upper_arm_link_1"/>
    <child link="elbow_link_1"/>
    <axis xyz="-0.018527 -0.999821 0.003722"/>
  </joint>
  <joint name="forearm_joint" type="revolute">
    <origin rpy="0 0 0" xyz="-0.001772 -0.213336 0.051748"/>
    <parent link="elbow_link_1"/>
    <child link="forearm_link_1"/>
    <axis xyz="0.014132 -0.004862 0.999888"/>
    <limit effort="100" lower="-1.570796" upper="1.570796" velocity="100"/>
  </joint>
  <joint name="wrist_roll_joint" type="continuous">
    <origin rpy="0 0 0" xyz="0.005726 -0.086993 -0.052701"/>
    <parent link="forearm_link_1"/>
    <child link="wrist_roll_link_1"/>
    <axis xyz="0.001449 -0.999987 -0.004883"/>
  </joint>
  <joint name="wrist_pitch_joint" type="revolute">
    <origin rpy="0 0 0" xyz="-0.003473 -0.078872 -0.029444"/>
    <parent link="wrist_roll_link_1"/>
    <child link="wrist_pitch_link_1"/>
    <axis xyz="-0.016941 0.015616 -0.999735"/>
    <limit effort="100" lower="-1.570796" upper="1.570796" velocity="100"/>
  </joint>
  <joint name="gripper_joint" type="continuous">
    <origin rpy="0 0 0" xyz="0.016903 -0.065732 0.040827"/>
    <parent link="wrist_pitch_link_1"/>
    <child link="claw_link_1"/>
    <axis xyz="0.045626 -0.998872 -0.013127"/>
  </joint>
  <joint name="tool_joint" type="prismatic">
    <origin rpy="0 0 0" xyz="0.000229 -0.026581 0.04995"/>
    <parent link="claw_link_1"/>
    <child link="tool_link_1"/>
    <axis xyz="-0.003468 0.012982 -0.99991"/>
    <limit effort="100" lower="-0.05" upper="0.01" velocity="100"/>
  </joint>
  <joint name="castor2_wheel_joint\" type="continuous">
    <origin rpy="0 0 0" xyz="0.014019 0.006948 -0.020931"/>
    <parent link="castor2_link_1"/>
    <child link="castor2_wheel_link_1"/>
    <axis xyz="-0.003747 -0.999993 0.0"/>
  </joint>
  <joint name="castor2_joint" type="continuous">
    <origin rpy="0 0 0" xyz="-0.181264 -0.178803 0.037117"/>
    <parent link="base_link"/>
    <child link="castor2_link_1"/>
    <axis xyz="-0.0 -0.0 -1.0"/>
  </joint>
  <joint name="castor1_wheel_joint" type="continuous">
    <origin rpy="0 0 0" xyz="-0.01395 -0.00678 -0.021147"/>
    <parent link="castor1_link_1"/>
    <child link="castor1_wheel_link_1"/>
    <axis xyz="0.015812 0.999875 0.0"/>
  </joint>
  <joint name="castor1_joint" type="continuous">
    <origin rpy="0 0 0" xyz="0.158401 -0.184256 0.037117"/>
    <parent link="base_link"/>
    <child link="castor1_link_1"/>
    <axis xyz="-0.0 0.0 -1.0"/>
  </joint>
  <joint name="castor4_wheel_joint" type="continuous">
    <origin rpy="0 0 0" xyz="-0.013907 0.007052 -0.02142"/>
    <parent link="castor4_link_1"/>
    <child link="castor4_wheel_link_1"/>
    <axis xyz="-0.003747 -0.999993 -0.0"/>
  </joint>
  <joint name="castor4_joint" type="continuous">
    <origin rpy="0 0 0" xyz="-0.17717 0.183789 0.037117"/>
    <parent link="base_link"/>
    <child link="castor4_link_1"/>
    <axis xyz="-0.0 0.0 -1.0"/>
  </joint>
  <joint name="castor3_wheel_joint" type="continuous">
    <origin rpy="0 0 0" xyz="-0.013931 0.007051 -0.021233"/>
    <parent link="castor3_link_1"/>
    <child link="castor3_wheel_link_1"/>
    <axis xyz="-0.003747 -0.999993 -0.0"/>
  </joint>
  <joint name="castor_joint" type="continuous">
    <origin rpy="0 0 0" xyz="0.160147 0.178597 0.037117"/>
    <parent link="base_link"/>
    <child link="castor3_link_1"/>
    <axis xyz="-0.0 0.0 -1.0"/>
  </joint>
</robot>
